Workbook
Name UPDATE: 'Data Sheet'!$E$1

Sheet Profit & Loss
A1: ='Data Sheet'!B1 -> HINDUSTAN UNILEVER LTD | H1: =UPDATE | M1: SCREENER.IN
A3: Narration | B3: ='Data Sheet'!B16 -> 42825 | C3: ='Data Sheet'!C16 -> 43190 | D3: ='Data Sheet'!D16 -> 43555 | E3: ='Data Sheet'!E16 -> 43921 | F3: ='Data Sheet'!F16 -> 44286 | G3: ='Data Sheet'!G16 -> 44651 | H3: ='Data Sheet'!H16 -> 45016 | I3: ='Data Sheet'!I16 -> 45382 | ... K3: ='Data Sheet'!K16 -> 46112 | L3: Trailing | M3: Best Case | N3: Worst Case
A4: Sales | B4: ='Data Sheet'!B17 -> 33162 | C4: ='Data Sheet'!C17 -> 35545 | D4: ='Data Sheet'!D17 -> 39310 | E4: ='Data Sheet'!E17 -> 39783 | F4: ='Data Sheet'!F17 -> 47028 | G4: ='Data Sheet'!G17 -> 52446 | H4: ='Data Sheet'!H17 -> 60580 | I4: ='Data Sheet'!I17 -> 61896 | ... K4: ='Data Sheet'!K17 -> 64468 | L4: =SUM(Quarters!H4:K4) -> 65225 | M4: =$K4+M23*K4 -> 67768.768 | N4: =$K4+N23*L4 -> 65834.541
A5: Expenses | B5: =SUM('Data Sheet'!B18,'Data Sheet'!B20:B24, -1*'Data Sheet'!B19) -> 26834 | C5: =SUM('Data Sheet'!C18,'Data Sheet'!C20:C24, -1*'Data Sheet'!C19) -> 28046 | D5: =SUM('Data Sheet'!D18,'Data Sheet'!D20:D24, -1*'Data Sheet'!D19) -> 30430 | E5: =SUM('Data Sheet'!E18,'Data Sheet'!E20:E24, -1*'Data Sheet'!E19) -> 29922 | F5: =SUM('Data Sheet'!F18,'Data Sheet'!F20:F24, -1*'Data Sheet'!F19) -> 35402 | G5: =SUM('Data Sheet'!G18,'Data Sheet'!G20:G24, -1*'Data Sheet'!G19) -> 39589 | H5: =SUM('Data Sheet'!H18,'Data Sheet'!H20:H24, -1*'Data Sheet'!H19) -> 46433 | I5: =SUM('Data Sheet'!I18,'Data Sheet'!I20:I24, -1*'Data Sheet'!I19) -> 47237 | ... K5: =SUM('Data Sheet'!K18,'Data Sheet'!K20:K24, -1*'Data Sheet'!K19) -> 49429 | L5: =SUM(Quarters!H5:K5) -> 50108 | M5: =M4-M6 -> 51738.984 | N5: =N4-N6 -> 50576.269
A6: Operating Profit | B6: =B4-B5 -> 6328 | C6: =C4-C5 -> 7499 | D6: =D4-D5 -> 8880 | E6: =E4-E5 -> 9861 | F6: =F4-F5 -> 11626 | G6: =G4-G5 -> 12857 | H6: =H4-H5 -> 14147 | I6: =I4-I5 -> 14659 | ... K6: =K4-K5 -> 15039 | L6: =SUM(Quarters!H6:K6) -> 15117 | M6: =M4*M24 -> 16029.784 | N6: =N4*N24 -> 15258.271
A7: Other Income | B7: ='Data Sheet'!B25 -> 606 | C7: ='Data Sheet'!C25 -> 353 | D7: ='Data Sheet'!D25 -> 322 | E7: ='Data Sheet'!E25 -> 424 | F7: ='Data Sheet'!F25 -> 170 | G7: ='Data Sheet'!G25 -> 219 | H7: ='Data Sheet'!H25 -> 448 | I7: ='Data Sheet'!I25 -> 817 | ... K7: ='Data Sheet'!K25 -> 4923 | L7: =SUM(Quarters!H7:K7) -> 4894 | M7: 0 | N7: 0
A8: Depreciation | B8: ='Data Sheet'!B26 -> 432 | C8: ='Data Sheet'!C26 -> 520 | D8: ='Data Sheet'!D26 -> 565 | E8: ='Data Sheet'!E26 -> 1002 | F8: ='Data Sheet'!F26 -> 1074 | G8: ='Data Sheet'!G26 -> 1091 | H8: ='Data Sheet'!H26 -> 1137 | I8: ='Data Sheet'!I26 -> 1216 | ... K8: ='Data Sheet'!K26 -> 1333 | L8: =SUM(Quarters!H8:K8) -> 1368 | M8: =+$L8 -> 1368 | N8: =+$L8 -> 1368
A9: Interest | B9: ='Data Sheet'!B27 -> 35 | C9: ='Data Sheet'!C27 -> 26 | D9: ='Data Sheet'!D27 -> 33 | E9: ='Data Sheet'!E27 -> 118 | F9: ='Data Sheet'!F27 -> 117 | G9: ='Data Sheet'!G27 -> 106 | H9: ='Data Sheet'!H27 -> 114 | I9: ='Data Sheet'!I27 -> 334 | ... K9: ='Data Sheet'!K27 -> 410 | L9: =SUM(Quarters!H9:K9) -> 415 | M9: =+$L9 -> 415 | N9: =+$L9 -> 415
A10: Profit before tax | B10: ='Data Sheet'!B28 -> 6467 | C10: ='Data Sheet'!C28 -> 7306 | D10: ='Data Sheet'!D28 -> 8604 | E10: ='Data Sheet'!E28 -> 9165 | F10: ='Data Sheet'!F28 -> 10605 | G10: ='Data Sheet'!G28 -> 11879 | H10: ='Data Sheet'!H28 -> 13344 | I10: ='Data Sheet'!I28 -> 13926 | ... K10: ='Data Sheet'!K28 -> 18219 | L10: =SUM(Quarters!H10:K10) -> 18228 | M10: =M6+M7-SUM(M8:M9) -> 14246.784 | N10: =N6+N7-SUM(N8:N9) -> 13475.271
A11: Tax | B11: ='Data Sheet'!B29 -> 1977 | C11: ='Data Sheet'!C29 -> 2079 | D11: ='Data Sheet'!D29 -> 2544 | E11: ='Data Sheet'!E29 -> 2409 | F11: ='Data Sheet'!F29 -> 2606 | G11: ='Data Sheet'!G29 -> 2987 | H11: ='Data Sheet'!H29 -> 3201 | I11: ='Data Sheet'!I29 -> 3644 | ... K11: ='Data Sheet'!K29 -> 3160 | L11: =SUM(Quarters!H11:K11) -> 3169 | M11: =IF($L10>0,$L11/$L10,0) -> 0.17385341 | N11: =IF($L10>0,$L11/$L10,0) -> 0.17385341
A12: Net profit | B12: ='Data Sheet'!B30 -> 4476 | C12: ='Data Sheet'!C30 -> 5214 | D12: ='Data Sheet'!D30 -> 6054 | E12: ='Data Sheet'!E30 -> 6748 | F12: ='Data Sheet'!F30 -> 7995 | G12: ='Data Sheet'!G30 -> 8879 | H12: ='Data Sheet'!H30 -> 10120 | I12: ='Data Sheet'!I30 -> 10277 | ... K12: ='Data Sheet'!K30 -> 15040 | L12: =SUM(Quarters!H12:K12) -> 15040 | M12: =M10-M11*M10 -> 11769.932 | N12: =N10-N11*N10 -> 11132.55
A13: EPS | B13: =IF('Data Sheet'!B93>0,B12/'Data Sheet'!B93,0) -> 20.681052 | C13: =IF('Data Sheet'!C93>0,C12/'Data Sheet'!C93,0) -> 24.088704 | D13: =IF('Data Sheet'!D93>0,D12/'Data Sheet'!D93,0) -> 27.966924 | E13: =IF('Data Sheet'!E93>0,E12/'Data Sheet'!E93,0) -> 31.171471 | F13: =IF('Data Sheet'!F93>0,F12/'Data Sheet'!F93,0) -> 34.027068 | G13: =IF('Data Sheet'!G93>0,G12/'Data Sheet'!G93,0) -> 37.789411 | H13: =IF('Data Sheet'!H93>0,H12/'Data Sheet'!H93,0) -> 43.071161 | I13: =IF('Data Sheet'!I93>0,I12/'Data Sheet'!I93,0) -> 43.73936 | ... K13: =IF('Data Sheet'!K93>0,K12/'Data Sheet'!K93,0) -> 64.010895 | L13: =IF('Data Sheet'!$B6>0,'Profit & Loss'!L12/'Data Sheet'!$B6,0) -> 64.01113 | M13: =IF('Data Sheet'!$B6>0,'Profit & Loss'!M12/'Data Sheet'!$B6,0) -> 50.093527 | N13: =IF('Data Sheet'!$B6>0,'Profit & Loss'!N12/'Data Sheet'!$B6,0) -> 47.380789
A14: Price to earning | B14: =IF(B15>0,B15/B13,"") -> 42.193696 | C14: =IF(C15>0,C15/C13,"") -> 52.975453 | D14: =IF(D15>0,D15/D13,"") -> 58.409356 | E14: =IF(E15>0,E15/E13,"") -> 70.571903 | F14: =IF(F15>0,F15/F13,"") -> 68.390258 | G14: =IF(G15>0,G15/G13,"") -> 51.884905 | H14: =IF(H15>0,H15/H13,"") -> 56.892824 | I14: =IF(I15>0,I15/I13,"") -> 49.546678 | ... K14: =IF(K15>0,K15/K13,"") -> 32.107034 | L14: =IF(L13>0,L15/L13,0) -> 33.619154 | M14: =M25 -> 40.74317 | N14: =N25 -> 33.619154
A15: Price | B15: ='Data Sheet'!B90 -> 872.61 | C15: ='Data Sheet'!C90 -> 1276.11 | D15: ='Data Sheet'!D90 -> 1633.53 | E15: ='Data Sheet'!E90 -> 2199.83 | F15: ='Data Sheet'!F90 -> 2327.12 | G15: ='Data Sheet'!G90 -> 1960.7 | H15: ='Data Sheet'!H90 -> 2450.44 | I15: ='Data Sheet'!I90 -> 2167.14 | ... K15: ='Data Sheet'!K90 -> 2055.2 | L15: ='Data Sheet'!B8 -> 2152 | M15: =M13*M14 -> 2040.9691 | N15: =N13*N14 -> 1592.902
A17: RATIOS:
A18: Dividend Payout | B18: =IF('Data Sheet'!B30>0, 'Data Sheet'!B31/'Data Sheet'!B30, 0) -> 0.82037534 | C18: =IF('Data Sheet'!C30>0, 'Data Sheet'!C31/'Data Sheet'!C30, 0) -> 0.82853855 | D18: =IF('Data Sheet'!D30>0, 'Data Sheet'!D31/'Data Sheet'!D30, 0) -> 0.78493558 | E18: =IF('Data Sheet'!E30>0, 'Data Sheet'!E31/'Data Sheet'!E30, 0) -> 0.80023711 | F18: =IF('Data Sheet'!F30>0, 'Data Sheet'!F31/'Data Sheet'!F30, 0) -> 1.1904315 | G18: =IF('Data Sheet'!G30>0, 'Data Sheet'!G31/'Data Sheet'!G30, 0) -> 0.89987611 | H18: =IF('Data Sheet'!H30>0, 'Data Sheet'!H31/'Data Sheet'!H30, 0) -> 0.90563241 | I18: =IF('Data Sheet'!I30>0, 'Data Sheet'!I31/'Data Sheet'!I30, 0) -> 0.960397 | ... K18: =IF('Data Sheet'!K30>0, 'Data Sheet'!K31/'Data Sheet'!K30, 0) -> 0.640625
A19: OPM | B19: =IF(B6>0,B6/B4,0) -> 0.19082082 | C19: =IF(C6>0,C6/C4,0) -> 0.21097201 | D19: =IF(D6>0,D6/D4,0) -> 0.22589672 | E19: =IF(E6>0,E6/E4,0) -> 0.24786969 | F19: =IF(F6>0,F6/F4,0) -> 0.24721443 | G19: =IF(G6>0,G6/G4,0) -> 0.24514739 | H19: =IF(H6>0,H6/H4,0) -> 0.23352592 | I19: =IF(I6>0,I6/I4,0) -> 0.23683275 | ... L19: =IF(L6>0,L6/L4,0) -> 0.23176696
G22: TRENDS: | H22: 10 YEARS | I22: 7 YEARS | J22: 5 YEARS | K22: 3 YEARS | L22: RECENT | M22: BEST | N22: WORST
G23: Sales Growth | H23: =IF(B4=0,"",POWER($K4/B4,1/9)-1) -> 0.076658974 | I23: =IF(D4=0,"",POWER($K4/D4,1/7)-1) -> 0.073227008 | J23: =IF(F4=0,"",POWER($K4/F4,1/5)-1) -> 0.065117542 | K23: =IF(H4=0,"",POWER($K4/H4, 1/3)-1) -> 0.020951182 | L23: =IF(ISERROR(MAX(IF(J4=0,"",(K4-J4)/J4),IF(K4=0,"",(L4-K4)/K4))),"",MAX(IF(J4=0,"",(K4-J4)/J4),IF(K4=0,"",(L4-K4)/K4))) -> 0.051200104 | M23: =MAX(K23:L23) -> 0.051200104 | N23: =MIN(H23:L23) -> 0.020951182
G24: OPM | H24: =IF(SUM(B4:$K$4)=0,"",SUMPRODUCT(B19:$K$19,B4:$K$4)/SUM(B4:$K$4)) -> 0.23326593 | I24: =IF(SUM(E4:$K$4)=0,"",SUMPRODUCT(E19:$K$19,E4:$K$4)/SUM(E4:$K$4)) -> 0.23969045 | J24: =IF(SUM(G4:$K$4)=0,"",SUMPRODUCT(G19:$K$19,G4:$K$4)/SUM(G4:$K$4)) -> 0.23743175 | K24: =IF(SUM(I4:$K$4)=0, "", SUMPRODUCT(I19:$K$19,I4:$K$4)/SUM(I4:$K$4)) -> 0.23653645 | L24: =L19 -> 0.23176696 | M24: =MAX(K24:L24) -> 0.23653645 | N24: =MIN(H24:L24) -> 0.23176696
G25: Price to Earning | H25: =IF(ISERROR(AVERAGEIF(B14:$L14,">0")),"",AVERAGEIF(B14:$L14,">0")) -> 51.299189 | I25: =IF(ISERROR(AVERAGEIF(E14:$L14,">0")),"",AVERAGEIF(E14:$L14,">0")) -> 51.339071 | J25: =IF(ISERROR(AVERAGEIF(G14:$L14,">0")),"",AVERAGEIF(G14:$L14,">0")) -> 45.291735 | K25: =IF(ISERROR(AVERAGEIF(I14:$L14,">0")),"",AVERAGEIF(I14:$L14,">0")) -> 40.74317 | L25: =L14 -> 33.619154 | M25: =MAX(K25:L25) -> 40.74317 | N25: =MIN(H25:L25) -> 33.619154

Sheet Quarters
A1: ='Profit & Loss'!A1 -> HINDUSTAN UNILEVER LTD | E1: =UPDATE | J1: SCREENER.IN
A3: Narration | B3: ='Data Sheet'!B41 -> 45291 | C3: ='Data Sheet'!C41 -> 45382 | D3: ='Data Sheet'!D41 -> 45473 | E3: ='Data Sheet'!E41 -> 45565 | F3: ='Data Sheet'!F41 -> 45657 | G3: ='Data Sheet'!G41 -> 45747 | H3: ='Data Sheet'!H41 -> 45838 | I3: ='Data Sheet'!I41 -> 45930 | ... K3: ='Data Sheet'!K41 -> 46112
A4: Sales | B4: ='Data Sheet'!B42 -> 15567 | C4: ='Data Sheet'!C42 -> 15210 | D4: ='Data Sheet'!D42 -> 15707 | E4: ='Data Sheet'!E42 -> 15926 | F4: ='Data Sheet'!F42 -> 15556 | G4: ='Data Sheet'!G42 -> 15190 | H4: ='Data Sheet'!H42 -> 16514 | I4: ='Data Sheet'!I42 -> 15919 | ... K4: ='Data Sheet'!K42 -> 16351
A5: Expenses | B5: ='Data Sheet'!B43 -> 11902 | C5: ='Data Sheet'!C43 -> 11675 | D5: ='Data Sheet'!D43 -> 11965 | E5: ='Data Sheet'!E43 -> 12139 | F5: ='Data Sheet'!F43 -> 11867 | G5: ='Data Sheet'!G43 -> 11572 | H5: ='Data Sheet'!H43 -> 12797 | I5: ='Data Sheet'!I43 -> 12137 | ... K5: ='Data Sheet'!K43 -> 12514
A6: Operating Profit | B6: ='Data Sheet'!B50 -> 3665 | C6: ='Data Sheet'!C50 -> 3535 | D6: ='Data Sheet'!D50 -> 3742 | E6: ='Data Sheet'!E50 -> 3787 | F6: ='Data Sheet'!F50 -> 3689 | G6: ='Data Sheet'!G50 -> 3618 | H6: ='Data Sheet'!H50 -> 3717 | I6: ='Data Sheet'!I50 -> 3782 | ... K6: ='Data Sheet'!K50 -> 3837
A7: Other Income | B7: ='Data Sheet'!B44 -> 184 | C7: ='Data Sheet'!C44 -> 309 | D7: ='Data Sheet'!D44 -> 209 | E7: ='Data Sheet'!E44 -> 203 | F7: ='Data Sheet'!F44 -> 733 | G7: ='Data Sheet'!G44 -> 149 | H7: ='Data Sheet'!H44 -> 74 | I7: ='Data Sheet'!I44 -> 269 | ... K7: ='Data Sheet'!K44 -> 503
A8: Depreciation | B8: ='Data Sheet'!B45 -> 313 | C8: ='Data Sheet'!C45 -> 320 | D8: ='Data Sheet'!D45 -> 329 | E8: ='Data Sheet'!E45 -> 338 | F8: ='Data Sheet'!F45 -> 318 | G8: ='Data Sheet'!G45 -> 318 | H8: ='Data Sheet'!H45 -> 361 | I8: ='Data Sheet'!I45 -> 322 | ... K8: ='Data Sheet'!K45 -> 348
A9: Interest | B9: ='Data Sheet'!B46 -> 91 | C9: ='Data Sheet'!C46 -> 105 | D9: ='Data Sheet'!D46 -> 93 | E9: ='Data Sheet'!E46 -> 110 | F9: ='Data Sheet'!F46 -> 109 | G9: ='Data Sheet'!G46 -> 77 | H9: ='Data Sheet'!H46 -> 127 | I9: ='Data Sheet'!I46 -> 124 | ... K9: ='Data Sheet'!K46 -> 76
A10: Profit before tax | B10: ='Data Sheet'!B47 -> 3445 | C10: ='Data Sheet'!C47 -> 3419 | D10: ='Data Sheet'!D47 -> 3529 | E10: ='Data Sheet'!E47 -> 3542 | F10: ='Data Sheet'!F47 -> 3995 | G10: ='Data Sheet'!G47 -> 3372 | H10: ='Data Sheet'!H47 -> 3303 | I10: ='Data Sheet'!I47 -> 3605 | ... K10: ='Data Sheet'!K47 -> 3916
A11: Tax | B11: ='Data Sheet'!B48 -> 937 | C11: ='Data Sheet'!C48 -> 858 | D11: ='Data Sheet'!D48 -> 917 | E11: ='Data Sheet'!E48 -> 947 | F11: ='Data Sheet'!F48 -> 1006 | G11: ='Data Sheet'!G48 -> 897 | H11: ='Data Sheet'!H48 -> 535 | I11: ='Data Sheet'!I48 -> 911 | ... K11: ='Data Sheet'!K48 -> 922
A12: Net profit | B12: ='Data Sheet'!B49 -> 2509 | C12: ='Data Sheet'!C49 -> 2558 | D12: ='Data Sheet'!D49 -> 2610 | E12: ='Data Sheet'!E49 -> 2591 | F12: ='Data Sheet'!F49 -> 2984 | G12: ='Data Sheet'!G49 -> 2464 | H12: ='Data Sheet'!H49 -> 2756 | I12: ='Data Sheet'!I49 -> 2685 | ... K12: ='Data Sheet'!K49 -> 2992
A14: OPM | B14: =IF(B4>0,B6/B4,"") -> 0.23543393 | C14: =IF(C4>0,C6/C4,"") -> 0.23241289 | D14: =IF(D4>0,D6/D4,"") -> 0.23823773 | E14: =IF(E4>0,E6/E4,"") -> 0.23778727 | F14: =IF(F4>0,F6/F4,"") -> 0.23714322 | G14: =IF(G4>0,G6/G4,"") -> 0.23818302 | H14: =IF(H4>0,H6/H4,"") -> 0.22508175 | I14: =IF(I4>0,I6/I4,"") -> 0.23757774 | ... K14: =IF(K4>0,K6/K4,"") -> 0.23466455

Sheet Balance Sheet
A1: ='Profit & Loss'!A1 -> HINDUSTAN UNILEVER LTD | E1: =UPDATE | J1: SCREENER.IN
A3: Narration | B3: ='Data Sheet'!B56 -> 42825 | C3: ='Data Sheet'!C56 -> 43190 | D3: ='Data Sheet'!D56 -> 43555 | E3: ='Data Sheet'!E56 -> 43921 | F3: ='Data Sheet'!F56 -> 44286 | G3: ='Data Sheet'!G56 -> 44651 | H3: ='Data Sheet'!H56 -> 45016 | I3: ='Data Sheet'!I56 -> 45382 | ... K3: ='Data Sheet'!K56 -> 46112
A4: Equity Share Capital | B4: ='Data Sheet'!B57 -> 216 | C4: ='Data Sheet'!C57 -> 216 | D4: ='Data Sheet'!D57 -> 216 | E4: ='Data Sheet'!E57 -> 216 | F4: ='Data Sheet'!F57 -> 235 | G4: ='Data Sheet'!G57 -> 235 | H4: ='Data Sheet'!H57 -> 235 | I4: ='Data Sheet'!I57 -> 235 | ... K4: ='Data Sheet'!K57 -> 235
A5: Reserves | B5: ='Data Sheet'!B58 -> 6528 | C5: ='Data Sheet'!C58 -> 7065 | D5: ='Data Sheet'!D58 -> 7651 | E5: ='Data Sheet'!E58 -> 8013 | F5: ='Data Sheet'!F58 -> 47439 | G5: ='Data Sheet'!G58 -> 48826 | H5: ='Data Sheet'!H58 -> 50069 | I5: ='Data Sheet'!I58 -> 50983 | ... K5: ='Data Sheet'!K58 -> 48504
A6: Borrowings | B6: ='Data Sheet'!B59 -> 277 | C6: ='Data Sheet'!C59 -> 0 | D6: ='Data Sheet'!D59 -> 99 | E6: ='Data Sheet'!E59 -> 0 | F6: ='Data Sheet'!F59 -> 0 | G6: ='Data Sheet'!G59 -> 1043 | H6: ='Data Sheet'!H59 -> 1219 | I6: ='Data Sheet'!I59 -> 1484 | ... K6: ='Data Sheet'!K59 -> 1478
A7: Other Liabilities | B7: ='Data Sheet'!B60 -> 8685 | C7: ='Data Sheet'!C60 -> 10581 | D7: ='Data Sheet'!D60 -> 10663 | E7: ='Data Sheet'!E60 -> 11924 | F7: ='Data Sheet'!F60 -> 21066 | G7: ='Data Sheet'!G60 -> 20402 | H7: ='Data Sheet'!H60 -> 21554 | I7: ='Data Sheet'!I60 -> 25787 | ... K7: ='Data Sheet'!K60 -> 29521
A8: Total | B8: ='Data Sheet'!B61 -> 15706 | C8: ='Data Sheet'!C61 -> 17862 | D8: ='Data Sheet'!D61 -> 18629 | E8: ='Data Sheet'!E61 -> 20153 | F8: ='Data Sheet'!F61 -> 68740 | G8: ='Data Sheet'!G61 -> 70506 | H8: ='Data Sheet'!H61 -> 73077 | I8: ='Data Sheet'!I61 -> 78489 | ... K8: ='Data Sheet'!K61 -> 79738
A10: Net Block | B10: ='Data Sheet'!B62 -> 4419 | C10: ='Data Sheet'!C62 -> 4528 | D10: ='Data Sheet'!D62 -> 4715 | E10: ='Data Sheet'!E62 -> 5479 | F10: ='Data Sheet'!F62 -> 51443 | G10: ='Data Sheet'!G62 -> 51473 | H10: ='Data Sheet'!H62 -> 52678 | I10: ='Data Sheet'!I62 -> 53744 | ... K10: ='Data Sheet'!K62 -> 57428
A11: Capital Work in Progress | B11: ='Data Sheet'!B63 -> 229 | C11: ='Data Sheet'!C63 -> 461 | D11: ='Data Sheet'!D63 -> 406 | E11: ='Data Sheet'!E63 -> 597 | F11: ='Data Sheet'!F63 -> 745 | G11: ='Data Sheet'!G63 -> 1313 | H11: ='Data Sheet'!H63 -> 1132 | I11: ='Data Sheet'!I63 -> 1025 | ... K11: ='Data Sheet'!K63 -> 880
A12: Investments | B12: ='Data Sheet'!B64 -> 3794 | C12: ='Data Sheet'!C64 -> 2873 | D12: ='Data Sheet'!D64 -> 2716 | E12: ='Data Sheet'!E64 -> 1255 | F12: ='Data Sheet'!F64 -> 2709 | G12: ='Data Sheet'!G64 -> 3521 | H12: ='Data Sheet'!H64 -> 2882 | I12: ='Data Sheet'!I64 -> 4625 | ... K12: ='Data Sheet'!K64 -> 4359
A13: Other Assets | B13: ='Data Sheet'!B65 -> 7264 | C13: ='Data Sheet'!C65 -> 10000 | D13: ='Data Sheet'!D65 -> 10792 | E13: ='Data Sheet'!E65 -> 12822 | F13: ='Data Sheet'!F65 -> 13843 | G13: ='Data Sheet'!G65 -> 14199 | H13: ='Data Sheet'!H65 -> 16385 | I13: ='Data Sheet'!I65 -> 19095 | ... K13: ='Data Sheet'!K65 -> 17071
A14: Total | B14: ='Data Sheet'!B66 -> 15706 | C14: ='Data Sheet'!C66 -> 17862 | D14: ='Data Sheet'!D66 -> 18629 | E14: ='Data Sheet'!E66 -> 20153 | F14: ='Data Sheet'!F66 -> 68740 | G14: ='Data Sheet'!G66 -> 70506 | H14: ='Data Sheet'!H66 -> 73077 | I14: ='Data Sheet'!I66 -> 78489 | ... K14: ='Data Sheet'!K66 -> 79738
A16: Working Capital | B16: =B13-B7 -> -1421 | C16: =C13-C7 -> -581 | D16: =D13-D7 -> 129 | E16: =E13-E7 -> 898 | F16: =F13-F7 -> -7223 | G16: =G13-G7 -> -6203 | H16: =H13-H7 -> -5169 | I16: =I13-I7 -> -6692 | ... K16: =K13-K7 -> -12450
A17: Debtors | B17: ='Data Sheet'!B67 -> 1085 | C17: ='Data Sheet'!C67 -> 1310 | D17: ='Data Sheet'!D67 -> 1816 | E17: ='Data Sheet'!E67 -> 1149 | F17: ='Data Sheet'!F67 -> 1758 | G17: ='Data Sheet'!G67 -> 2236 | H17: ='Data Sheet'!H67 -> 3079 | I17: ='Data Sheet'!I67 -> 2997 | ... K17: ='Data Sheet'!K67 -> 3379
A18: Inventory | B18: ='Data Sheet'!B68 -> 2541 | C18: ='Data Sheet'!C68 -> 2513 | D18: ='Data Sheet'!D68 -> 2574 | E18: ='Data Sheet'!E68 -> 2767 | F18: ='Data Sheet'!F68 -> 3579 | G18: ='Data Sheet'!G68 -> 4096 | H18: ='Data Sheet'!H68 -> 4251 | I18: ='Data Sheet'!I68 -> 4022 | ... K18: ='Data Sheet'!K68 -> 4789
A20: Debtor Days | B20: =IF('Profit & Loss'!B4>0,'Balance Sheet'!B17/('Profit & Loss'!B4/365),0) -> 11.942133 | C20: =IF('Profit & Loss'!C4>0,'Balance Sheet'!C17/('Profit & Loss'!C4/365),0) -> 13.451962 | D20: =IF('Profit & Loss'!D4>0,'Balance Sheet'!D17/('Profit & Loss'!D4/365),0) -> 16.861867 | E20: =IF('Profit & Loss'!E4>0,'Balance Sheet'!E17/('Profit & Loss'!E4/365),0) -> 10.541814 | F20: =IF('Profit & Loss'!F4>0,'Balance Sheet'!F17/('Profit & Loss'!F4/365),0) -> 13.644425 | G20: =IF('Profit & Loss'!G4>0,'Balance Sheet'!G17/('Profit & Loss'!G4/365),0) -> 15.56153 | H20: =IF('Profit & Loss'!H4>0,'Balance Sheet'!H17/('Profit & Loss'!H4/365),0) -> 18.551255 | I20: =IF('Profit & Loss'!I4>0,'Balance Sheet'!I17/('Profit & Loss'!I4/365),0) -> 17.673275 | ... K20: =IF('Profit & Loss'!K4>0,'Balance Sheet'!K17/('Profit & Loss'!K4/365),0) -> 19.130964
A21: Inventory Turnover | B21: =IF('Balance Sheet'!B18>0,'Profit & Loss'!B4/'Balance Sheet'!B18,0) -> 13.050767 | C21: =IF('Balance Sheet'!C18>0,'Profit & Loss'!C4/'Balance Sheet'!C18,0) -> 14.144449 | D21: =IF('Balance Sheet'!D18>0,'Profit & Loss'!D4/'Balance Sheet'!D18,0) -> 15.27195 | E21: =IF('Balance Sheet'!E18>0,'Profit & Loss'!E4/'Balance Sheet'!E18,0) -> 14.377665 | F21: =IF('Balance Sheet'!F18>0,'Profit & Loss'!F4/'Balance Sheet'!F18,0) -> 13.139983 | G21: =IF('Balance Sheet'!G18>0,'Profit & Loss'!G4/'Balance Sheet'!G18,0) -> 12.804199 | H21: =IF('Balance Sheet'!H18>0,'Profit & Loss'!H4/'Balance Sheet'!H18,0) -> 14.250765 | I21: =IF('Balance Sheet'!I18>0,'Profit & Loss'!I4/'Balance Sheet'!I18,0) -> 15.389359 | ... K21: =IF('Balance Sheet'!K18>0,'Profit & Loss'!K4/'Balance Sheet'!K18,0) -> 13.461683
A23: Return on Equity | B23: =IF(SUM('Balance Sheet'!B4:B5)>0,'Profit & Loss'!B12/SUM('Balance Sheet'!B4:B5),"") -> 0.66370107 | C23: =IF(SUM('Balance Sheet'!C4:C5)>0,'Profit & Loss'!C12/SUM('Balance Sheet'!C4:C5),"") -> 0.71611042 | D23: =IF(SUM('Balance Sheet'!D4:D5)>0,'Profit & Loss'!D12/SUM('Balance Sheet'!D4:D5),"") -> 0.76954366 | E23: =IF(SUM('Balance Sheet'!E4:E5)>0,'Profit & Loss'!E12/SUM('Balance Sheet'!E4:E5),"") -> 0.82002673 | F23: =IF(SUM('Balance Sheet'!F4:F5)>0,'Profit & Loss'!F12/SUM('Balance Sheet'!F4:F5),"") -> 0.16770147 | G23: =IF(SUM('Balance Sheet'!G4:G5)>0,'Profit & Loss'!G12/SUM('Balance Sheet'!G4:G5),"") -> 0.18097878 | H23: =IF(SUM('Balance Sheet'!H4:H5)>0,'Profit & Loss'!H12/SUM('Balance Sheet'!H4:H5),"") -> 0.20117684 | I23: =IF(SUM('Balance Sheet'!I4:I5)>0,'Profit & Loss'!I12/SUM('Balance Sheet'!I4:I5),"") -> 0.20065211 | ... K23: =IF(SUM('Balance Sheet'!K4:K5)>0,'Profit & Loss'!K12/SUM('Balance Sheet'!K4:K5),"") -> 0.30858245
A24: Return on Capital Emp | C24: =IF((B4+B5+B6+C4+C5+C6)>0,('Profit & Loss'!C10+'Profit & Loss'!C9)*2/(B4+B5+B6+C4+C5+C6),"") -> 1.0253111 | D24: =IF((C4+C5+C6+D4+D5+D6)>0,('Profit & Loss'!D10+'Profit & Loss'!D9)*2/(C4+C5+C6+D4+D5+D6),"") -> 1.1329442 | E24: =IF((D4+D5+D6+E4+E5+E6)>0,('Profit & Loss'!E10+'Profit & Loss'!E9)*2/(D4+D5+D6+E4+E5+E6),"") -> 1.1464032 | F24: =IF((E4+E5+E6+F4+F5+F6)>0,('Profit & Loss'!F10+'Profit & Loss'!F9)*2/(E4+E5+E6+F4+F5+F6),"") -> 0.38359301 | G24: =IF((F4+F5+F6+G4+G5+G6)>0,('Profit & Loss'!G10+'Profit & Loss'!G9)*2/(F4+F5+F6+G4+G5+G6),"") -> 0.24514717 | H24: =IF((G4+G5+G6+H4+H5+H6)>0,('Profit & Loss'!H10+'Profit & Loss'!H9)*2/(G4+G5+G6+H4+H5+H6),"") -> 0.26485088 | I24: =IF((H4+H5+H6+I4+I5+I6)>0,('Profit & Loss'!I10+'Profit & Loss'!I9)*2/(H4+H5+H6+I4+I5+I6),"") -> 0.27363876 | J24: =IF((I4+I5+I6+J4+J5+J6)>0,('Profit & Loss'!J10+'Profit & Loss'!J9)*2/(I4+I5+I6+J4+J5+J6),"") -> 0.28529571 | K24: =IF((J4+J5+J6+K4+K5+K6)>0,('Profit & Loss'!K10+'Profit & Loss'!K9)*2/(J4+J5+J6+K4+K5+K6),"") -> 0.36791847

Sheet Cash Flow
A1: ='Balance Sheet'!A1 -> HINDUSTAN UNILEVER LTD | E1: =UPDATE | J1: SCREENER.IN
A3: Narration | B3: ='Data Sheet'!B81 -> 42825 | C3: ='Data Sheet'!C81 -> 43190 | D3: ='Data Sheet'!D81 -> 43555 | E3: ='Data Sheet'!E81 -> 43921 | F3: ='Data Sheet'!F81 -> 44286 | G3: ='Data Sheet'!G81 -> 44651 | H3: ='Data Sheet'!H81 -> 45016 | I3: ='Data Sheet'!I81 -> 45382 | ... K3: ='Data Sheet'!K81 -> 46112
A4: Cash from Operating Activity | B4: ='Data Sheet'!B82 -> 5185 | C4: ='Data Sheet'!C82 -> 6059 | D4: ='Data Sheet'!D82 -> 5800 | E4: ='Data Sheet'!E82 -> 7623 | F4: ='Data Sheet'!F82 -> 9163 | G4: ='Data Sheet'!G82 -> 9048 | H4: ='Data Sheet'!H82 -> 9991 | I4: ='Data Sheet'!I82 -> 15469 | ... K4: ='Data Sheet'!K82 -> 10999
A5: Cash from Investing Activity | B5: ='Data Sheet'!B83 -> -1173 | C5: ='Data Sheet'!C83 -> -1063 | D5: ='Data Sheet'!D83 -> -438 | E5: ='Data Sheet'!E83 -> 1791 | F5: ='Data Sheet'!F83 -> -1228 | G5: ='Data Sheet'!G83 -> -1728 | H5: ='Data Sheet'!H83 -> -1484 | I5: ='Data Sheet'!I83 -> -5324 | ... K5: ='Data Sheet'!K83 -> -3676
A6: Cash from Financing Activity | B6: ='Data Sheet'!B84 -> -4214 | C6: ='Data Sheet'!C84 -> -4975 | D6: ='Data Sheet'!D84 -> -5390 | E6: ='Data Sheet'!E84 -> -6819 | F6: ='Data Sheet'!F84 -> -9309 | G6: ='Data Sheet'!G84 -> -8015 | H6: ='Data Sheet'!H84 -> -8953 | I6: ='Data Sheet'!I84 -> -10034 | ... K6: ='Data Sheet'!K84 -> -10810
A7: Net Cash Flow | B7: ='Data Sheet'!B85 -> -202 | C7: ='Data Sheet'!C85 -> 21 | D7: ='Data Sheet'!D85 -> -28 | E7: ='Data Sheet'!E85 -> 2595 | F7: ='Data Sheet'!F85 -> -1374 | G7: ='Data Sheet'!G85 -> -695 | H7: ='Data Sheet'!H85 -> -446 | I7: ='Data Sheet'!I85 -> 111 | ... K7: ='Data Sheet'!K85 -> -3487

Sheet Customization
A1: How to use it?
A3: You can customize this workbook as you want.
B4: You can add custom formating, add conditional formating, add your own formulas… do ANYTHING.
B5: Please don't edit the "Data Sheet" only.
A7: After customization, you can upload this back on Screener.
B8: Upload on: | C8: https://www.screener.in/excel/
A10: Download your customized workbooks now onwards.
B11: Now whenever you will "Export to excel" from Screener, it will export your customized file.
A14: TESTING:
B15: This is a testing feature currently.
B16: You can report any formula errors on the worksheet at: support@screener.in

Sheet Data Sheet
A1: COMPANY NAME | B1: HINDUSTAN UNILEVER LTD | E1: =IF(B2<>B3, "A NEW VERSION OF THE WORKSHEET IS AVAILABLE", "")
A2: LATEST VERSION | B2: 2.1 | E2: PLEASE DO NOT MAKE ANY CHANGES TO THIS SHEET
A3: CURRENT VERSION | B3: 2.1
A5: META
A6: Number of shares | B6: =IF(B9>0, B9/B8, 0) -> 234.95914
A7: Face Value | B7: 1
A8: Current Price | B8: 2152
A9: Market Capitalization | B9: 505632.07
A15: PROFIT & LOSS
A16: Report Date | B16: 42825 | C16: 43190 | D16: 43555 | E16: 43921 | F16: 44286 | G16: 44651 | H16: 45016 | I16: 45382 | J16: 45747 | K16: 46112
A17: Sales | B17: 33162 | C17: 35545 | D17: 39310 | E17: 39783 | F17: 47028 | G17: 52446 | H17: 60580 | I17: 61896 | J17: 61328 | K17: 64468
A18: Raw Material Cost | B18: 13606 | C18: 14233 | D18: 15845 | E18: 15697 | F18: 20141 | G18: 22871 | H18: 28427 | I18: 26822 | J18: 26602 | K18: 29158
A19: Change in Inventory | B19: -144 | C19: 72 | D19: -12 | E19: 108 | F19: 405 | G19: 22 | H19: 75 | I19: 11 | J19: 125 | K19: 429
A20: Power and Fuel | B20: 295 | C20: 295 | D20: 308 | E20: 299 | F20: 339 | G20: 318 | H20: 384 | I20: 446 | J20: 403 | K20: 426
A21: Other Mfr. Exp | B21: 2887 | C21: 2998 | D21: 3041 | E21: 2906 | F21: 2868 | G21: 3354 | H21: 3791 | I21: 3385 | J21: 3687 | K21: 3304
A22: Employee Cost | B22: 1743 | C22: 1860 | D22: 1875 | E22: 1820 | F22: 2358 | G22: 2545 | H22: 2854 | I22: 3009 | J22: 2952 | K22: 3175
A23: Selling and admin | B23: 6689 | C23: 7252 | D23: 7796 | E23: 7620 | F23: 7906 | G23: 8164 | H23: 8785 | I23: 10780 | J23: 10145 | K23: 10744
A24: Other Expenses | B24: 1470 | C24: 1480 | D24: 1553 | E24: 1688 | F24: 2195 | G24: 2359 | H24: 2267 | I24: 2806 | J24: 2966 | K24: 3051
A25: Other Income | B25: 606 | C25: 353 | D25: 322 | E25: 424 | F25: 170 | G25: 219 | H25: 448 | I25: 817 | J25: 1355 | K25: 4923
A26: Depreciation | B26: 432 | C26: 520 | D26: 565 | E26: 1002 | F26: 1074 | G26: 1091 | H26: 1137 | I26: 1216 | J26: 1253 | K26: 1333
A27: Interest | B27: 35 | C27: 26 | D27: 33 | E27: 118 | F27: 117 | G27: 106 | H27: 114 | I27: 334 | J27: 381 | K27: 410
... A31: Dividend Amount | B31: 3672 | C31: 4320 | D31: 4752 | E31: 5400 | F31: 9517.5 | G31: 7990 | H31: 9165 | I31: 9870 | J31: 12455 | K31: 9635
A32: EBITDA | B32: =SUM(B26:B28) -> 6934 | C32: =SUM(C26:C28) -> 7852 | D32: =SUM(D26:D28) -> 9202 | E32: =SUM(E26:E28) -> 10285 | F32: =SUM(F26:F28) -> 11796 | G32: =SUM(G26:G28) -> 13076 | H32: =SUM(H26:H28) -> 14595 | I32: =SUM(I26:I28) -> 15476 | ... K32: =SUM(K26:K28) -> 19962
A33: EBIT | B33: =SUM(B27:B28) -> 6502 | C33: =SUM(C27:C28) -> 7332 | D33: =SUM(D27:D28) -> 8637 | E33: =SUM(E27:E28) -> 9283 | F33: =SUM(F27:F28) -> 10722 | G33: =SUM(G27:G28) -> 11985 | H33: =SUM(H27:H28) -> 13458 | I33: =SUM(I27:I28) -> 14260 | ... K33: =SUM(K27:K28) -> 18629
A40: Quarters
A41: Report Date | B41: 45291 | C41: 45382 | D41: 45473 | E41: 45565 | F41: 45657 | G41: 45747 | H41: 45838 | I41: 45930 | J41: 46022 | K41: 46112
A42: Sales | B42: 15567 | C42: 15210 | D42: 15707 | E42: 15926 | F42: 15556 | G42: 15190 | H42: 16514 | I42: 15919 | J42: 16441 | K42: 16351
A43: Expenses | B43: 11902 | C43: 11675 | D43: 11965 | E43: 12139 | F43: 11867 | G43: 11572 | H43: 12797 | I43: 12137 | J43: 12660 | K43: 12514
A44: Other Income | B44: 184 | C44: 309 | D44: 209 | E44: 203 | F44: 733 | G44: 149 | H44: 74 | I44: 269 | J44: 4048 | K44: 503
A45: Depreciation | B45: 313 | C45: 320 | D45: 329 | E45: 338 | F45: 318 | G45: 318 | H45: 361 | I45: 322 | J45: 337 | K45: 348
A46: Interest | B46: 91 | C46: 105 | D46: 93 | E46: 110 | F46: 109 | G46: 77 | H46: 127 | I46: 124 | J46: 88 | K46: 76
A47: Profit before tax | B47: 3445 | C47: 3419 | D47: 3529 | E47: 3542 | F47: 3995 | G47: 3372 | H47: 3303 | I47: 3605 | J47: 7404 | K47: 3916
A48: Tax | B48: 937 | C48: 858 | D48: 917 | E48: 947 | F48: 1006 | G48: 897 | H48: 535 | I48: 911 | J48: 801 | K48: 922
A49: Net profit | B49: 2509 | C49: 2558 | D49: 2610 | E49: 2591 | F49: 2984 | G49: 2464 | H49: 2756 | I49: 2685 | J49: 6607 | K49: 2992
A50: Operating Profit | B50: 3665 | C50: 3535 | D50: 3742 | E50: 3787 | F50: 3689 | G50: 3618 | H50: 3717 | I50: 3782 | J50: 3781 | K50: 3837
A55: BALANCE SHEET
A56: Report Date | B56: 42825 | C56: 43190 | D56: 43555 | E56: 43921 | F56: 44286 | G56: 44651 | H56: 45016 | I56: 45382 | J56: 45747 | K56: 46112
A57: Equity Share Capital | B57: 216 | C57: 216 | D57: 216 | E57: 216 | F57: 235 | G57: 235 | H57: 235 | I57: 235 | J57: 235 | K57: 235
A58: Reserves | B58: 6528 | C58: 7065 | D58: 7651 | E58: 8013 | F58: 47439 | G58: 48826 | H58: 50069 | I58: 50983 | J58: 49167 | K58: 48504
A59: Borrowings | B59: 277 | D59: 99 | G59: 1043 | H59: 1219 | I59: 1484 | J59: 1648 | K59: 1478
...

Sheet Historical FS
B2: ="Historical Financial Statement for " &'Data Sheet'!B1 -> Historical Financial Statement for HINDUSTAN UNILEVER LTD
B3: Year | C3: ='Data Sheet'!B16 -> 42825 | D3: ='Data Sheet'!C16 -> 43190 | E3: ='Data Sheet'!D16 -> 43555 | F3: ='Data Sheet'!E16 -> 43921 | G3: ='Data Sheet'!F16 -> 44286 | H3: ='Data Sheet'!G16 -> 44651 | I3: ='Data Sheet'!H16 -> 45016 | J3: ='Data Sheet'!I16 -> 45382 | ... L3: ='Data Sheet'!K16 -> 46112 | M3: =L3+365 -> 46477 | N3: =M3+365 -> 46842 | O3: =N3+365 -> 47207 | P3: =O3+365 -> 47572 | Q3: =P3+365 -> 47937
A5: # | B5: Income Statement
B6: ='Data Sheet'!A17 -> Sales | C6: ='Data Sheet'!B17 -> 33162 | D6: ='Data Sheet'!C17 -> 35545 | E6: ='Data Sheet'!D17 -> 39310 | F6: ='Data Sheet'!E17 -> 39783 | G6: ='Data Sheet'!F17 -> 47028 | H6: ='Data Sheet'!G17 -> 52446 | I6: ='Data Sheet'!H17 -> 60580 | ... L6: ='Data Sheet'!K17 -> 64468 | M6: =FORECAST($M$3,C6:L6,$C$3:$L$3) -> 70982.404 | N6: =FORECAST($M$3,D6:M6,$C$3:$L$3) -> 75182.241 | O6: =FORECAST($M$3,E6:N6,$C$3:$L$3) -> 79176.45 | P6: =FORECAST($M$3,F6:O6,$C$3:$L$3) -> 83129.771 | Q6: =FORECAST($M$3,G6:P6,$C$3:$L$3) -> 86132.088
B7: Sales Growth | C7: - | D7: =D6/C6-1 -> 0.071859357 | E7: =E6/D6-1 -> 0.10592207 | F7: =F6/E6-1 -> 0.012032562 | G7: =G6/F6-1 -> 0.18211296 | H7: =H6/G6-1 -> 0.11520796 | I7: =I6/H6-1 -> 0.15509286 | J7: =J6/I6-1 -> 0.021723341 | K7: =K6/J6-1 -> -0.0091766835 | ... Q7: =Q6/P6-1 -> 0.036116025
B9: COGS | C9: =SUM('Data Sheet'!B18:B22) -> 18387 | D9: =SUM('Data Sheet'!C18:C22) -> 19458 | E9: =SUM('Data Sheet'!D18:D22) -> 21057 | F9: =SUM('Data Sheet'!E18:E22) -> 20830 | G9: =SUM('Data Sheet'!F18:F22) -> 26111 | H9: =SUM('Data Sheet'!G18:G22) -> 29110 | I9: =SUM('Data Sheet'!H18:H22) -> 35531 | J9: =SUM('Data Sheet'!I18:I22) -> 33673 | ... L9: =SUM('Data Sheet'!K18:K22) -> 36492 | M9: =FORECAST($M$3,C9:L9,$C$3:$L$3) -> 39882.336 | N9: =FORECAST($M$3,D9:M9,$C$3:$L$3) -> 42444.255 | O9: =FORECAST($M$3,E9:N9,$C$3:$L$3) -> 44883.444 | P9: =FORECAST($M$3,F9:O9,$C$3:$L$3) -> 47192.178 | Q9: =FORECAST($M$3,G9:P9,$C$3:$L$3) -> 48774.908
B11: Gross Profit | C11: =C6-C9 -> 14775 | D11: =D6-D9 -> 16087 | E11: =E6-E9 -> 18253 | F11: =F6-F9 -> 18953 | G11: =G6-G9 -> 20917 | H11: =H6-H9 -> 23336 | I11: =I6-I9 -> 25049 | J11: =J6-J9 -> 28223 | ... L11: =L6-L9 -> 27976 | M11: =FORECAST($M$3,C11:L11,$C$3:$L$3) -> 31100.068 | N11: =FORECAST($M$3,D11:M11,$C$3:$L$3) -> 32737.986 | O11: =FORECAST($M$3,E11:N11,$C$3:$L$3) -> 34293.006 | P11: =FORECAST($M$3,F11:O11,$C$3:$L$3) -> 35937.593 | Q11: =FORECAST($M$3,G11:P11,$C$3:$L$3) -> 37357.18
B12: Gross Profit Margins | C12: =C11/C6 -> 0.44554008 | D12: =D11/D6 -> 0.45258124 | E12: =E11/E6 -> 0.46433477 | F12: =F11/F6 -> 0.47640952 | G12: =G11/G6 -> 0.44477758 | H12: =H11/H6 -> 0.4449529 | I12: =I11/I6 -> 0.4134863 | J12: =J11/J6 -> 0.45597454 | ... Q12: =Q11/Q6 -> 0.43371966
C13: ='Historical FS'!C40/SUM('Historical FS'!D3) -> 0.0064135216
B14: Selling and General Expenses | C14: =SUM('Data Sheet'!B23:B24) -> 8159 | D14: =SUM('Data Sheet'!C23:C24) -> 8732 | E14: =SUM('Data Sheet'!D23:D24) -> 9349 | F14: =SUM('Data Sheet'!E23:E24) -> 9308 | G14: =SUM('Data Sheet'!F23:F24) -> 10101 | H14: =SUM('Data Sheet'!G23:G24) -> 10523 | I14: =SUM('Data Sheet'!H23:H24) -> 11052 | J14: =SUM('Data Sheet'!I23:I24) -> 13586 | ... L14: =SUM('Data Sheet'!K23:K24) -> 13795 | M14: =FORECAST($M$3,C14:L14,$C$3:$L$3) -> 14378.169 | N14: =FORECAST($M$3,D14:M14,$C$3:$L$3) -> 15123.927 | O14: =FORECAST($M$3,E14:N14,$C$3:$L$3) -> 15906.342 | P14: =FORECAST($M$3,F14:O14,$C$3:$L$3) -> 16740.151 | Q14: =FORECAST($M$3,G14:P14,$C$3:$L$3) -> 17459.517
B16: EBITDA | C16: =C11-C14 -> 6616 | D16: =D11-D14 -> 7355 | E16: =E11-E14 -> 8904 | F16: =F11-F14 -> 9645 | G16: =G11-G14 -> 10816 | H16: =H11-H14 -> 12813 | I16: =I11-I14 -> 13997 | J16: =J11-J14 -> 14637 | ... L16: =L11-L14 -> 14181 | M16: =FORECAST($M$3,C16:L16,$C$3:$L$3) -> 16721.899 | N16: =FORECAST($M$3,D16:M16,$C$3:$L$3) -> 17614.059 | O16: =FORECAST($M$3,E16:N16,$C$3:$L$3) -> 18386.663 | P16: =FORECAST($M$3,F16:O16,$C$3:$L$3) -> 19197.442 | Q16: =FORECAST($M$3,G16:P16,$C$3:$L$3) -> 19897.663
B17: EBITDA Margins | C17: =C16/C6 -> 0.19950546 | D17: =D16/D6 -> 0.2069208 | E17: =E16/E6 -> 0.22650725 | F17: =F16/F6 -> 0.24244024 | G17: =G16/G6 -> 0.22999064 | H17: =H16/H6 -> 0.24430843 | I17: =I16/I6 -> 0.23104985 | J17: =J16/J6 -> 0.23647732 | ... Q17: =Q16/Q6 -> 0.23101337
B19: D&A | C19: ='Data Sheet'!B26 -> 432 | D19: ='Data Sheet'!C26 -> 520 | E19: ='Data Sheet'!D26 -> 565 | F19: ='Data Sheet'!E26 -> 1002 | G19: ='Data Sheet'!F26 -> 1074 | H19: ='Data Sheet'!G26 -> 1091 | I19: ='Data Sheet'!H26 -> 1137 | J19: ='Data Sheet'!I26 -> 1216 | ... L19: ='Data Sheet'!K26 -> 1333 | M19: =FORECAST($M$3,C19:L19,$C$3:$L$3) -> 1526.1118 | N19: =FORECAST($M$3,D19:M19,$C$3:$L$3) -> 1610.1984 | O19: =FORECAST($M$3,E19:N19,$C$3:$L$3) -> 1678.4709 | P19: =FORECAST($M$3,F19:O19,$C$3:$L$3) -> 1713.4074 | Q19: =FORECAST($M$3,G19:P19,$C$3:$L$3) -> 1804.5766
B21: EBIT | C21: =C16-C19 -> 6184 | D21: =D16-D19 -> 6835 | E21: =E16-E19 -> 8339 | F21: =F16-F19 -> 8643 | G21: =G16-G19 -> 9742 | H21: =H16-H19 -> 11722 | I21: =I16-I19 -> 12860 | J21: =J16-J19 -> 13421 | ... L21: =L16-L19 -> 12848 | M21: =FORECAST($M$3,C21:L21,$C$3:$L$3) -> 15195.788 | N21: =FORECAST($M$3,D21:M21,$C$3:$L$3) -> 16003.861 | O21: =FORECAST($M$3,E21:N21,$C$3:$L$3) -> 16708.192 | P21: =FORECAST($M$3,F21:O21,$C$3:$L$3) -> 17484.035 | Q21: =FORECAST($M$3,G21:P21,$C$3:$L$3) -> 18093.087
B22: EBIT Margins | C22: =C21/C6 -> 0.1864785 | D22: =D21/D6 -> 0.19229146 | E22: =E21/E6 -> 0.21213432 | F22: =F21/F6 -> 0.2172536 | G22: =G21/G6 -> 0.20715319 | H22: =H21/H6 -> 0.22350608 | I22: =I21/I6 -> 0.21228128 | J22: =J21/J6 -> 0.21683146 | ... Q22: =Q21/Q6 -> 0.2100621
B24: Interest | C24: ='Data Sheet'!B27 -> 35 | D24: ='Data Sheet'!C27 -> 26 | E24: ='Data Sheet'!D27 -> 33 | F24: ='Data Sheet'!E27 -> 118 | G24: ='Data Sheet'!F27 -> 117 | H24: ='Data Sheet'!G27 -> 106 | I24: ='Data Sheet'!H27 -> 114 | J24: ='Data Sheet'!I27 -> 334 | ... L24: ='Data Sheet'!K27 -> 410 | M24: =FORECAST($M$3,C24:L24,$C$3:$L$3) -> 412.10221 | N24: =FORECAST($M$3,D24:M24,$C$3:$L$3) -> 474.65326 | O24: =FORECAST($M$3,E24:N24,$C$3:$L$3) -> 534.69462 | P24: =FORECAST($M$3,F24:O24,$C$3:$L$3) -> 590.72629 | Q24: =FORECAST($M$3,G24:P24,$C$3:$L$3) -> 658.40186
B26: EBT | C26: =C21-C24 -> 6149 | D26: =D21-D24 -> 6809 | E26: =E21-E24 -> 8306 | F26: =F21-F24 -> 8525 | G26: =G21-G24 -> 9625 | H26: =H21-H24 -> 11616 | I26: =I21-I24 -> 12746 | J26: =J21-J24 -> 13087 | ... L26: =L21-L24 -> 12438 | M26: =FORECAST($M$3,C26:L26,$C$3:$L$3) -> 14783.685 | N26: =FORECAST($M$3,D26:M26,$C$3:$L$3) -> 15529.208 | O26: =FORECAST($M$3,E26:N26,$C$3:$L$3) -> 16173.498 | P26: =FORECAST($M$3,F26:O26,$C$3:$L$3) -> 16893.308 | Q26: =FORECAST($M$3,G26:P26,$C$3:$L$3) -> 17434.685
B27: EBT Margins | C27: =C26/C6 -> 0.18542307 | D27: =D26/D6 -> 0.19155999 | E27: =E26/E6 -> 0.21129484 | F27: =F26/F6 -> 0.21428751 | G27: =G26/G6 -> 0.20466531 | H27: =H26/H6 -> 0.22148496 | I27: =I26/I6 -> 0.21039947 | J27: =J26/J6 -> 0.21143531 | ... Q27: =Q26/Q6 -> 0.202418
B29: Tax | C29: ='Data Sheet'!B29 -> 1977 | D29: ='Data Sheet'!C29 -> 2079 | E29: ='Data Sheet'!D29 -> 2544 | F29: ='Data Sheet'!E29 -> 2409 | G29: ='Data Sheet'!F29 -> 2606 | H29: ='Data Sheet'!G29 -> 2987 | I29: ='Data Sheet'!H29 -> 3201 | J29: ='Data Sheet'!I29 -> 3644 | ... L29: ='Data Sheet'!K29 -> 3160 | M29: =FORECAST($M$3,C29:L29,$C$3:$L$3) -> 3854.8744 | N29: =FORECAST($M$3,D29:M29,$C$3:$L$3) -> 4033.6585 | O29: =FORECAST($M$3,E29:N29,$C$3:$L$3) -> 4185.9915 | P29: =FORECAST($M$3,F29:O29,$C$3:$L$3) -> 4393.0207 | Q29: =FORECAST($M$3,G29:P29,$C$3:$L$3) -> 4537.3295
B31: Net Profit | C31: =C26-C29 -> 4172 | D31: =D26-D29 -> 4730 | E31: =E26-E29 -> 5762 | F31: =F26-F29 -> 6116 | G31: =G26-G29 -> 7019 | H31: =H26-H29 -> 8629 | I31: =I26-I29 -> 9545 | J31: =J26-J29 -> 9443 | ... L31: =L26-L29 -> 9278 | M31: =FORECAST($M$3,C31:L31,$C$3:$L$3) -> 10928.811 | N31: =FORECAST($M$3,D31:M31,$C$3:$L$3) -> 11495.549 | O31: =FORECAST($M$3,E31:N31,$C$3:$L$3) -> 11987.506 | P31: =FORECAST($M$3,F31:O31,$C$3:$L$3) -> 12500.288 | Q31: =FORECAST($M$3,G31:P31,$C$3:$L$3) -> 12897.356
B32: Net Profit Margins | C32: =C31/C6 -> 0.12580665 | D32: =D31/D6 -> 0.13307076 | E32: =E31/E6 -> 0.14657848 | F32: =F31/F6 -> 0.15373401 | G32: =G31/G6 -> 0.14925151 | H32: =H31/H6 -> 0.16453114 | I32: =I31/I6 -> 0.15756025 | J32: =J31/J6 -> 0.15256236 | ... Q32: =Q31/Q6 -> 0.14973927
A37: # | B37: Balance Sheet
B38: Equity Share Capital | C38: ='Data Sheet'!B57 -> 216 | D38: ='Data Sheet'!C57 -> 216 | E38: ='Data Sheet'!D57 -> 216 | F38: ='Data Sheet'!E57 -> 216 | G38: ='Data Sheet'!F57 -> 235 | H38: ='Data Sheet'!G57 -> 235 | I38: ='Data Sheet'!H57 -> 235 | J38: ='Data Sheet'!I57 -> 235 | ... L38: ='Data Sheet'!K57 -> 235 | M38: =FORECAST($M$3,C38:L38,$C$3:$L$3) -> 242.59678 | N38: =FORECAST($M$3,D38:M38,$C$3:$L$3) -> 245.63654 | O38: =FORECAST($M$3,E38:N38,$C$3:$L$3) -> 248.11695 | P38: =FORECAST($M$3,F38:O38,$C$3:$L$3) -> 249.6153 | Q38: =FORECAST($M$3,G38:P38,$C$3:$L$3) -> 249.57227
B39: Reserves | C39: ='Data Sheet'!B58 -> 6528 | D39: ='Data Sheet'!C58 -> 7065 | E39: ='Data Sheet'!D58 -> 7651 | F39: ='Data Sheet'!E58 -> 8013 | G39: ='Data Sheet'!F58 -> 47439 | H39: ='Data Sheet'!G58 -> 48826 | I39: ='Data Sheet'!H58 -> 50069 | J39: ='Data Sheet'!I58 -> 50983 | ... L39: ='Data Sheet'!K58 -> 48504 | M39: =FORECAST($M$3,C39:L39,$C$3:$L$3) -> 66307.82 | N39: =FORECAST($M$3,D39:M39,$C$3:$L$3) -> 72957.34 | O39: =FORECAST($M$3,E39:N39,$C$3:$L$3) -> 78420.603 | P39: =FORECAST($M$3,F39:O39,$C$3:$L$3) -> 81835.86 | Q39: =FORECAST($M$3,G39:P39,$C$3:$L$3) -> 81996.185
B40: Borrowings | C40: ='Data Sheet'!B59 -> 277 | D40: ='Data Sheet'!C59 -> 0 | E40: ='Data Sheet'!D59 -> 99 | F40: ='Data Sheet'!E59 -> 0 | G40: ='Data Sheet'!F59 -> 0 | H40: ='Data Sheet'!G59 -> 1043 | I40: ='Data Sheet'!H59 -> 1219 | J40: ='Data Sheet'!I59 -> 1484 | ... L40: ='Data Sheet'!K59 -> 1478 | M40: =FORECAST($M$3,C40:L40,$C$3:$L$3) -> 1856.8915 | N40: =FORECAST($M$3,D40:M40,$C$3:$L$3) -> 2190.2762 | O40: =FORECAST($M$3,E40:N40,$C$3:$L$3) -> 2477.8981 | P40: =FORECAST($M$3,F40:O40,$C$3:$L$3) -> 2760.8825 | Q40: =FORECAST($M$3,G40:P40,$C$3:$L$3) -> 2972.0985
B41: Other Liabilities | C41: ='Data Sheet'!B60-C42 -> 2499 | D41: ='Data Sheet'!C60-D42 -> 3411 | E41: ='Data Sheet'!D60-E42 -> 3457 | F41: ='Data Sheet'!E60-F42 -> 4389 | G41: ='Data Sheet'!F60-G42 -> 12264 | H41: ='Data Sheet'!G60-H42 -> 11334 | I41: ='Data Sheet'!H60-I42 -> 11980 | J41: ='Data Sheet'!I60-J42 -> 15301 | ... L41: ='Data Sheet'!K60-L42 -> 16196 | M41: =FORECAST($M$3,C41:L41,$C$3:$L$3) -> 19929.251 | N41: =FORECAST($M$3,D41:M41,$C$3:$L$3) -> 22012.28 | O41: =FORECAST($M$3,E41:N41,$C$3:$L$3) -> 24008.594 | P41: =FORECAST($M$3,F41:O41,$C$3:$L$3) -> 25576.954 | Q41: =FORECAST($M$3,G41:P41,$C$3:$L$3) -> 26651.242
B42: Trade Payables | C42: ='Manual Data'!D39 -> 6186 | D42: ='Manual Data'!E39 -> 7170 | E42: ='Manual Data'!F39 -> 7206 | F42: ='Manual Data'!G39 -> 7535 | G42: ='Manual Data'!H39 -> 8802 | H42: ='Manual Data'!I39 -> 9068 | I42: ='Manual Data'!J39 -> 9574 | J42: ='Manual Data'!K39 -> 10486 | ... L42: ='Manual Data'!M39 -> 13325 | M42: =FORECAST($M$3,C42:L42,$C$3:$L$3) -> 12934.192 | N42: =FORECAST($M$3,D42:M42,$C$3:$L$3) -> 13713.11 | O42: =FORECAST($M$3,E42:N42,$C$3:$L$3) -> 14615.924 | P42: =FORECAST($M$3,F42:O42,$C$3:$L$3) -> 15453.15 | Q42: =FORECAST($M$3,G42:P42,$C$3:$L$3) -> 16219.306
B44: Total Liablities | C44: =SUM(C38:C43) -> 15706 | D44: =SUM(D38:D43) -> 17862 | E44: =SUM(E38:E43) -> 18629 | F44: =SUM(F38:F43) -> 20153 | G44: =SUM(G38:G43) -> 68740 | H44: =SUM(H38:H43) -> 70506 | I44: =SUM(I38:I43) -> 73077 | J44: =SUM(J38:J43) -> 78489 | ... Q44: =SUM(Q38:Q43) -> 128088.4
B46: Net Block | C46: ='Data Sheet'!B62 -> 4419 | D46: ='Data Sheet'!C62 -> 4528 | E46: ='Data Sheet'!D62 -> 4715 | F46: ='Data Sheet'!E62 -> 5479 | G46: ='Data Sheet'!F62 -> 51443 | H46: ='Data Sheet'!G62 -> 51473 | I46: ='Data Sheet'!H62 -> 52678 | J46: ='Data Sheet'!I62 -> 53744 | ... L46: ='Data Sheet'!K62 -> 57428 | M46: =FORECAST($M$3,C46:L46,$C$3:$L$3) -> 74432.432 | N46: =FORECAST($M$3,D46:M46,$C$3:$L$3) -> 82703.451 | O46: =FORECAST($M$3,E46:N46,$C$3:$L$3) -> 89639.34 | P46: =FORECAST($M$3,F46:O46,$C$3:$L$3) -> 94191.227 | Q46: =FORECAST($M$3,G46:P46,$C$3:$L$3) -> 95107.224
B47: Capital Work in Progress | C47: ='Data Sheet'!B63 -> 229 | D47: ='Data Sheet'!C63 -> 461 | E47: ='Data Sheet'!D63 -> 406 | F47: ='Data Sheet'!E63 -> 597 | G47: ='Data Sheet'!F63 -> 745 | H47: ='Data Sheet'!G63 -> 1313 | I47: ='Data Sheet'!H63 -> 1132 | J47: ='Data Sheet'!I63 -> 1025 | ... L47: ='Data Sheet'!K63 -> 880 | M47: =FORECAST($M$3,C47:L47,$C$3:$L$3) -> 1278.3516 | N47: =FORECAST($M$3,D47:M47,$C$3:$L$3) -> 1330.9848 | O47: =FORECAST($M$3,E47:N47,$C$3:$L$3) -> 1396.5814 | P47: =FORECAST($M$3,F47:O47,$C$3:$L$3) -> 1415.7253 | Q47: =FORECAST($M$3,G47:P47,$C$3:$L$3) -> 1427.4112
B48: Investments | C48: ='Data Sheet'!B64 -> 3794 | D48: ='Data Sheet'!C64 -> 2873 | E48: ='Data Sheet'!D64 -> 2716 | F48: ='Data Sheet'!E64 -> 1255 | G48: ='Data Sheet'!F64 -> 2709 | H48: ='Data Sheet'!G64 -> 3521 | I48: ='Data Sheet'!H64 -> 2882 | J48: ='Data Sheet'!I64 -> 4625 | ... L48: ='Data Sheet'!K64 -> 4359 | M48: =FORECAST($M$3,C48:L48,$C$3:$L$3) -> 4150.2863 | N48: =FORECAST($M$3,D48:M48,$C$3:$L$3) -> 4652.4928 | O48: =FORECAST($M$3,E48:N48,$C$3:$L$3) -> 5086.2253 | P48: =FORECAST($M$3,F48:O48,$C$3:$L$3) -> 5532.7947 | Q48: =FORECAST($M$3,G48:P48,$C$3:$L$3) -> 5610.8479
B49: Other Assets | C49: ='Data Sheet'!B65-SUM('Data Sheet'!B67:B69) -> 1810 | D49: ='Data Sheet'!C65-SUM('Data Sheet'!C67:C69) -> 2692 | E49: ='Data Sheet'!D65-SUM('Data Sheet'!D67:D69) -> 2645 | F49: ='Data Sheet'!E65-SUM('Data Sheet'!E67:E69) -> 3793 | G49: ='Data Sheet'!F65-SUM('Data Sheet'!F67:F69) -> 4035 | H49: ='Data Sheet'!G65-SUM('Data Sheet'!G67:G69) -> 4021 | I49: ='Data Sheet'!H65-SUM('Data Sheet'!H67:H69) -> 4377 | J49: ='Data Sheet'!I65-SUM('Data Sheet'!I67:I69) -> 4517 | ... L49: ='Data Sheet'!K65-SUM('Data Sheet'!K67:K69) -> 5655 | M49: =FORECAST($M$3,C49:L49,$C$3:$L$3) -> 5889.7525 | N49: =FORECAST($M$3,D49:M49,$C$3:$L$3) -> 6163.9287 | O49: =FORECAST($M$3,E49:N49,$C$3:$L$3) -> 6510.9652 | P49: =FORECAST($M$3,F49:O49,$C$3:$L$3) -> 6752.8739 | Q49: =FORECAST($M$3,G49:P49,$C$3:$L$3) -> 7139.8831
B51: Total Non-Current Assets | C51: =SUM(C46:C50) -> 10252 | D51: =SUM(D46:D50) -> 10554 | E51: =SUM(E46:E50) -> 10482 | F51: =SUM(F46:F50) -> 11124 | G51: =SUM(G46:G50) -> 58932 | H51: =SUM(H46:H50) -> 60328 | I51: =SUM(I46:I50) -> 61069 | J51: =SUM(J46:J50) -> 63911 | ... Q51: =SUM(Q46:Q50) -> 109285.37
B52: Receivables | C52: ='Data Sheet'!B67 -> 1085 | D52: ='Data Sheet'!C67 -> 1310 | E52: ='Data Sheet'!D67 -> 1816 | F52: ='Data Sheet'!E67 -> 1149 | G52: ='Data Sheet'!F67 -> 1758 | H52: ='Data Sheet'!G67 -> 2236 | I52: ='Data Sheet'!H67 -> 3079 | J52: ='Data Sheet'!I67 -> 2997 | ... L52: ='Data Sheet'!K67 -> 3379 | M52: =FORECAST($M$3,C52:L52,$C$3:$L$3) -> 3941.7874 | N52: =FORECAST($M$3,D52:M52,$C$3:$L$3) -> 4299.3987 | O52: =FORECAST($M$3,E52:N52,$C$3:$L$3) -> 4669.4478 | P52: =FORECAST($M$3,F52:O52,$C$3:$L$3) -> 5123.2225 | Q52: =FORECAST($M$3,G52:P52,$C$3:$L$3) -> 5390.3826
B53: Inventory | C53: ='Data Sheet'!B68 -> 2541 | D53: ='Data Sheet'!C68 -> 2513 | E53: ='Data Sheet'!D68 -> 2574 | F53: ='Data Sheet'!E68 -> 2767 | G53: ='Data Sheet'!F68 -> 3579 | H53: ='Data Sheet'!G68 -> 4096 | I53: ='Data Sheet'!H68 -> 4251 | J53: ='Data Sheet'!I68 -> 4022 | ... L53: ='Data Sheet'!K68 -> 4789 | M53: =FORECAST($M$3,C53:L53,$C$3:$L$3) -> 5079.5218 | N53: =FORECAST($M$3,D53:M53,$C$3:$L$3) -> 5419.2054 | O53: =FORECAST($M$3,E53:N53,$C$3:$L$3) -> 5717.9675 | P53: =FORECAST($M$3,F53:O53,$C$3:$L$3) -> 5958.7304 | Q53: =FORECAST($M$3,G53:P53,$C$3:$L$3) -> 6137.7248
B54: Cash & Bank | C54: ='Data Sheet'!B69 -> 1828 | D54: ='Data Sheet'!C69 -> 3485 | E54: ='Data Sheet'!D69 -> 3757 | F54: ='Data Sheet'!E69 -> 5113 | G54: ='Data Sheet'!F69 -> 4471 | H54: ='Data Sheet'!G69 -> 3846 | I54: ='Data Sheet'!H69 -> 4678 | J54: ='Data Sheet'!I69 -> 7559 | ... L54: ='Data Sheet'!K69 -> 3248 | M54: =FORECAST($M$3,C54:L54,$C$3:$L$3) -> 6498.6198 | N54: =FORECAST($M$3,D54:M54,$C$3:$L$3) -> 6549.1808 | O54: =FORECAST($M$3,E54:N54,$C$3:$L$3) -> 6750.609 | P54: =FORECAST($M$3,F54:O54,$C$3:$L$3) -> 6901.8888 | Q54: =FORECAST($M$3,G54:P54,$C$3:$L$3) -> 7274.9294
B55: Total Current Assets | C55: =SUM(C52:C54) -> 5454 | D55: =SUM(D52:D54) -> 7308 | E55: =SUM(E52:E54) -> 8147 | F55: =SUM(F52:F54) -> 9029 | G55: =SUM(G52:G54) -> 9808 | H55: =SUM(H52:H54) -> 10178 | I55: =SUM(I52:I54) -> 12008 | J55: =SUM(J52:J54) -> 14578 | ... Q55: =SUM(Q52:Q54) -> 18803.037
B57: Total Assets | C57: =C51+C55 -> 15706 | D57: =D51+D55 -> 17862 | E57: =E51+E55 -> 18629 | F57: =F51+F55 -> 20153 | G57: =G51+G55 -> 68740 | H57: =H51+H55 -> 70506 | I57: =I51+I55 -> 73077 | J57: =J51+J55 -> 78489 | K57: =K51+K55 -> 79863 | L57: =SUM(L55,L51) -> 79738 | M57: =SUM(M55,M51) -> 101270.75 | N57: =SUM(N55,N51) -> 111118.64 | O57: =SUM(O55,O51) -> 119771.14 | P57: =SUM(P55,P51) -> 125876.46 | Q57: =SUM(Q55,Q51) -> 128088.4
A61: # | B61: Cash flow Satement
B62: Cash Flow from Operating Activity
...

Sheet Ratio Analysis
B2: ="Ratio Analysis for "&'Data Sheet'!B1 -> Ratio Analysis for HINDUSTAN UNILEVER LTD
B3: Year | C3: ='Historical FS'!C3 -> 42825 | D3: ='Historical FS'!D3 -> 43190 | E3: ='Historical FS'!E3 -> 43555 | F3: ='Historical FS'!F3 -> 43921 | G3: ='Historical FS'!G3 -> 44286 | H3: ='Historical FS'!H3 -> 44651 | I3: ='Historical FS'!I3 -> 45016 | J3: ='Historical FS'!J3 -> 45382 | ... Q3: ='Historical FS'!Q3 -> 47937
B4: Profitability Ratios
B5: Gross Profit Margin | C5: ='Historical FS'!C11/'Historical FS'!C6 -> 0.44554008 | D5: ='Historical FS'!D11/'Historical FS'!D6 -> 0.45258124 | E5: ='Historical FS'!E11/'Historical FS'!E6 -> 0.46433477 | F5: ='Historical FS'!F11/'Historical FS'!F6 -> 0.47640952 | G5: ='Historical FS'!G11/'Historical FS'!G6 -> 0.44477758 | H5: ='Historical FS'!H11/'Historical FS'!H6 -> 0.4449529 | I5: ='Historical FS'!I11/'Historical FS'!I6 -> 0.4134863 | J5: ='Historical FS'!J11/'Historical FS'!J6 -> 0.45597454 | ... Q5: ='Historical FS'!Q11/'Historical FS'!Q6 -> 0.43371966
B6: EBITDA Margins | C6: ='Historical FS'!C16/'Historical FS'!C6 -> 0.19950546 | D6: ='Historical FS'!D16/'Historical FS'!D6 -> 0.2069208 | E6: ='Historical FS'!E16/'Historical FS'!E6 -> 0.22650725 | F6: ='Historical FS'!F16/'Historical FS'!F6 -> 0.24244024 | G6: ='Historical FS'!G16/'Historical FS'!G6 -> 0.22999064 | H6: ='Historical FS'!H16/'Historical FS'!H6 -> 0.24430843 | I6: ='Historical FS'!I16/'Historical FS'!I6 -> 0.23104985 | J6: ='Historical FS'!J16/'Historical FS'!J6 -> 0.23647732 | ... Q6: ='Historical FS'!Q16/'Historical FS'!Q6 -> 0.23101337
B7: EBIT Margins | C7: ='Historical FS'!C21/'Historical FS'!C6 -> 0.1864785 | D7: ='Historical FS'!D21/'Historical FS'!D6 -> 0.19229146 | E7: ='Historical FS'!E21/'Historical FS'!E6 -> 0.21213432 | F7: ='Historical FS'!F21/'Historical FS'!F6 -> 0.2172536 | G7: ='Historical FS'!G21/'Historical FS'!G6 -> 0.20715319 | H7: ='Historical FS'!H21/'Historical FS'!H6 -> 0.22350608 | I7: ='Historical FS'!I21/'Historical FS'!I6 -> 0.21228128 | J7: ='Historical FS'!J21/'Historical FS'!J6 -> 0.21683146 | ... Q7: ='Historical FS'!Q21/'Historical FS'!Q6 -> 0.2100621
B8: Net Profit Margins | C8: ='Historical FS'!C31/'Historical FS'!C6 -> 0.12580665 | D8: ='Historical FS'!D31/'Historical FS'!D6 -> 0.13307076 | E8: ='Historical FS'!E31/'Historical FS'!E6 -> 0.14657848 | F8: ='Historical FS'!F31/'Historical FS'!F6 -> 0.15373401 | G8: ='Historical FS'!G31/'Historical FS'!G6 -> 0.14925151 | H8: ='Historical FS'!H31/'Historical FS'!H6 -> 0.16453114 | I8: ='Historical FS'!I31/'Historical FS'!I6 -> 0.15756025 | J8: ='Historical FS'!J31/'Historical FS'!J6 -> 0.15256236 | ... Q8: ='Historical FS'!Q31/'Historical FS'!Q6 -> 0.14973927
B9: Return on Assets | C9: ='Historical FS'!C31/'Historical FS'!C57 -> 0.26563097 | D9: ='Historical FS'!D31/'Historical FS'!D57 -> 0.26480797 | E9: ='Historical FS'!E31/'Historical FS'!E57 -> 0.3093027 | F9: ='Historical FS'!F31/'Historical FS'!F57 -> 0.30347839 | G9: ='Historical FS'!G31/'Historical FS'!G57 -> 0.1021094 | H9: ='Historical FS'!H31/'Historical FS'!H57 -> 0.12238675 | I9: ='Historical FS'!I31/'Historical FS'!I57 -> 0.13061565 | J9: ='Historical FS'!J31/'Historical FS'!J57 -> 0.12030985 | ... Q9: ='Historical FS'!Q31/'Historical FS'!Q57 -> 0.10069105
B10: Return on Equity | C10: ='Historical FS'!C31/SUM('Historical FS'!C38:C39) -> 0.61862396 | D10: ='Historical FS'!D31/SUM('Historical FS'!D38:D39) -> 0.64963604 | E10: ='Historical FS'!E31/SUM('Historical FS'!E38:E39) -> 0.73242659 | F10: ='Historical FS'!F31/SUM('Historical FS'!F38:F39) -> 0.74322518 | G10: ='Historical FS'!G31/SUM('Historical FS'!G38:G39) -> 0.1472291 | H10: ='Historical FS'!H31/SUM('Historical FS'!H38:H39) -> 0.17588308 | I10: ='Historical FS'!I31/SUM('Historical FS'!I38:I39) -> 0.18974634 | J10: ='Historical FS'!J31/SUM('Historical FS'!J38:J39) -> 0.18436878 | ... Q10: ='Historical FS'!Q31/SUM('Historical FS'!Q38:Q39) -> 0.15681484
B12: Solvency Ratios
B13: Debt/Equity | C13: ='Historical FS'!C40/SUM('Historical FS'!C38:C39) -> 0.041073547 | D13: ='Historical FS'!D40/SUM('Historical FS'!D38:D39) -> 0 | E13: ='Historical FS'!E40/SUM('Historical FS'!E38:E39) -> 0.012584213 | F13: ='Historical FS'!F40/SUM('Historical FS'!F38:F39) -> 0 | G13: ='Historical FS'!G40/SUM('Historical FS'!G38:G39) -> 0 | H13: ='Historical FS'!H40/SUM('Historical FS'!H38:H39) -> 0.021259249 | I13: ='Historical FS'!I40/SUM('Historical FS'!I38:I39) -> 0.024232665 | J13: ='Historical FS'!J40/SUM('Historical FS'!J38:J39) -> 0.028974189 | ... Q13: ='Historical FS'!Q40/SUM('Historical FS'!Q38:Q39) -> 0.0361368
B14: Debt Ratio | C14: ='Historical FS'!C40/'Historical FS'!C57 -> 0.017636572 | D14: ='Historical FS'!D40/'Historical FS'!D57 -> 0 | E14: ='Historical FS'!E40/'Historical FS'!E57 -> 0.0053142949 | F14: ='Historical FS'!F40/'Historical FS'!F57 -> 0 | G14: ='Historical FS'!G40/'Historical FS'!G57 -> 0 | H14: ='Historical FS'!H40/'Historical FS'!H57 -> 0.014793067 | I14: ='Historical FS'!I40/'Historical FS'!I57 -> 0.016681035 | J14: ='Historical FS'!J40/'Historical FS'!J57 -> 0.018907108 | ... Q14: ='Historical FS'!Q40/'Historical FS'!Q57 -> 0.023203494
B15: Interest Coverage Ratio | C15: ='Historical FS'!C21/'Historical FS'!C24 -> 176.68571 | D15: ='Historical FS'!D21/'Historical FS'!D24 -> 262.88462 | E15: ='Historical FS'!E21/'Historical FS'!E24 -> 252.69697 | F15: ='Historical FS'!F21/'Historical FS'!F24 -> 73.245763 | G15: ='Historical FS'!G21/'Historical FS'!G24 -> 83.264957 | H15: ='Historical FS'!H21/'Historical FS'!H24 -> 110.58491 | I15: ='Historical FS'!I21/'Historical FS'!I24 -> 112.80702 | J15: ='Historical FS'!J21/'Historical FS'!J24 -> 40.182635 | ... Q15: ='Historical FS'!Q21/'Historical FS'!Q24 -> 27.480309
B17: Efficiency Ratios
B18: Asset Turnover | C18: ='Historical FS'!C6/'Historical FS'!C57 -> 2.1114224 | D18: ='Historical FS'!D6/'Historical FS'!D57 -> 1.9899787 | E18: ='Historical FS'!E6/'Historical FS'!E57 -> 2.1101508 | F18: ='Historical FS'!F6/'Historical FS'!F57 -> 1.9740485 | G18: ='Historical FS'!G6/'Historical FS'!G57 -> 0.68414315 | H18: ='Historical FS'!H6/'Historical FS'!H57 -> 0.74385159 | I18: ='Historical FS'!I6/'Historical FS'!I57 -> 0.8289886 | J18: ='Historical FS'!J6/'Historical FS'!J57 -> 0.78859458 | ... Q18: ='Historical FS'!Q6/'Historical FS'!Q57 -> 0.67244251
B19: Inventory Turnover | C19: ='Historical FS'!C9/'Historical FS'!C53 -> 7.2361275 | D19: ='Historical FS'!D9/'Historical FS'!D53 -> 7.7429367 | E19: ='Historical FS'!E9/'Historical FS'!E53 -> 8.1806527 | F19: ='Historical FS'!F9/'Historical FS'!F53 -> 7.5280087 | G19: ='Historical FS'!G9/'Historical FS'!G53 -> 7.2956133 | H19: ='Historical FS'!H9/'Historical FS'!H53 -> 7.1069336 | I19: ='Historical FS'!I9/'Historical FS'!I53 -> 8.3582686 | J19: ='Historical FS'!J9/'Historical FS'!J53 -> 8.3722029 | ... Q19: ='Historical FS'!Q9/'Historical FS'!Q53 -> 7.9467407
B20: Receivables Turnover | C20: ='Historical FS'!C6/'Historical FS'!C52 -> 30.564055 | D20: ='Historical FS'!D6/'Historical FS'!D52 -> 27.133588 | E20: ='Historical FS'!E6/'Historical FS'!E52 -> 21.646476 | F20: ='Historical FS'!F6/'Historical FS'!F52 -> 34.624021 | G20: ='Historical FS'!G6/'Historical FS'!G52 -> 26.750853 | H20: ='Historical FS'!H6/'Historical FS'!H52 -> 23.455277 | I20: ='Historical FS'!I6/'Historical FS'!I52 -> 19.675219 | J20: ='Historical FS'!J6/'Historical FS'!J52 -> 20.652653 | ... Q20: ='Historical FS'!Q6/'Historical FS'!Q52 -> 15.978845
B21: Payable Turnover | C21: ='Historical FS'!C9/'Historical FS'!C42 -> 2.9723569 | D21: ='Historical FS'!D9/'Historical FS'!D42 -> 2.7138075 | E21: ='Historical FS'!E9/'Historical FS'!E42 -> 2.9221482 | F21: ='Historical FS'!F9/'Historical FS'!F42 -> 2.7644326 | G21: ='Historical FS'!G9/'Historical FS'!G42 -> 2.9664849 | H21: ='Historical FS'!H9/'Historical FS'!H42 -> 3.2101897 | I21: ='Historical FS'!I9/'Historical FS'!I42 -> 3.711197 | J21: ='Historical FS'!J9/'Historical FS'!J42 -> 3.211234 | ... Q21: ='Historical FS'!Q9/'Historical FS'!Q42 -> 3.0072131
B22: Fixed Asset Turnover | C22: ='Historical FS'!C6/'Historical FS'!C46 -> 7.5044128 | D22: ='Historical FS'!D6/'Historical FS'!D46 -> 7.8500442 | E22: ='Historical FS'!E6/'Historical FS'!E46 -> 8.3372216 | F22: ='Historical FS'!F6/'Historical FS'!F46 -> 7.2609965 | G22: ='Historical FS'!G6/'Historical FS'!G46 -> 0.91417686 | H22: ='Historical FS'!H6/'Historical FS'!H46 -> 1.0189031 | I22: ='Historical FS'!I6/'Historical FS'!I46 -> 1.1500057 | J22: ='Historical FS'!J6/'Historical FS'!J46 -> 1.151682 | ... Q22: ='Historical FS'!Q6/'Historical FS'!Q46 -> 0.90563139
B24: Liquidity Ratios
B25: Current Ratio | I25: ='Historical FS'!I55/'Manual Data'!J37 -> 0.99833721 | J25: ='Historical FS'!J55/'Manual Data'!K37 -> 1.1319202 | K25: ='Historical FS'!K55/'Manual Data'!L37 -> 0.95470763 | L25: ='Historical FS'!L55/'Manual Data'!M37 -> 0.73419513 | M25: =FORECAST($M$3,I25:L25,$I$3:$L$3) -> 0.71265255 | N25: =FORECAST($M$3,J25:M25,$I$3:$L$3) -> 0.51395587 | O25: =FORECAST($M$3,K25:N25,$I$3:$L$3) -> 0.39307923 | P25: =FORECAST($M$3,L25:O25,$I$3:$L$3) -> 0.28317841 | Q25: =FORECAST($M$3,M25:P25,$I$3:$L$3) -> 0.12354986
B26: Quick Ratio | I26: =('Historical FS'!I55-'Historical FS'!I53)/'Manual Data'!J37 -> 0.64491187 | J26: =('Historical FS'!J55-'Historical FS'!J53)/'Manual Data'!K37 -> 0.81962885 | K26: =('Historical FS'!K55-'Historical FS'!K53)/'Manual Data'!L37 -> 0.68773054 | L26: =('Historical FS'!L55-'Historical FS'!L53)/'Manual Data'!M37 -> 0.42620104 | M26: =FORECAST($M$3,I26:L26,$I$3:$L$3) -> 0.44787963 | N26: =FORECAST($M$3,J26:M26,$I$3:$L$3) -> 0.25133004 | O26: =FORECAST($M$3,K26:N26,$I$3:$L$3) -> 0.13152443 | P26: =FORECAST($M$3,L26:O26,$I$3:$L$3) -> 0.044305515 | Q26: =FORECAST($M$3,M26:P26,$I$3:$L$3) -> -0.11373023
B27: Cash Ratio | I27: ='Historical FS'!I54/'Manual Data'!J37 -> 0.38892584 | J27: ='Historical FS'!J54/'Manual Data'!K37 -> 0.58692445 | K27: ='Historical FS'!K54/'Manual Data'!L37 -> 0.45679386 | L27: ='Historical FS'!L54/'Manual Data'!M37 -> 0.20888803 | M27: =FORECAST($M$3,I27:L27,$I$3:$L$3) -> 0.24308074 | N27: =FORECAST($M$3,J27:M27,$I$3:$L$3) -> 0.054208948 | O27: =FORECAST($M$3,K27:N27,$I$3:$L$3) -> -0.05254159 | P27: =FORECAST($M$3,L27:O27,$I$3:$L$3) -> -0.12967875 | Q27: =FORECAST($M$3,M27:P27,$I$3:$L$3) -> -0.2773639
B29: Market Ratios
B30: Earning per Share | C30: ='Historical FS'!C31/'Data Sheet'!B93 -> 19.27644 | D30: ='Historical FS'!D31/'Data Sheet'!C93 -> 21.852622 | E30: ='Historical FS'!E31/'Data Sheet'!D93 -> 26.618007 | F30: ='Historical FS'!F31/'Data Sheet'!E93 -> 28.252033 | G30: ='Historical FS'!G31/'Data Sheet'!F93 -> 29.87317 | H30: ='Historical FS'!H31/'Data Sheet'!G93 -> 36.7254 | I30: ='Historical FS'!I31/'Data Sheet'!H93 -> 40.623936 | J30: ='Historical FS'!J31/'Data Sheet'!I93 -> 40.18982 | ... L30: ='Historical FS'!L31/'Data Sheet'!K93 -> 39.487572 | M30: =FORECAST($M$3,C30:L30,$C$3:$L$3) -> 45.840573 | N30: =FORECAST($M$3,D30:M30,$C$3:$L$3) -> 47.884842 | O30: =FORECAST($M$3,E30:N30,$C$3:$L$3) -> 49.663889 | P30: =FORECAST($M$3,F30:O30,$C$3:$L$3) -> 51.689134 | Q30: =FORECAST($M$3,G30:P30,$C$3:$L$3) -> 53.422917
B31: P/E ratio | C31: ='Data Sheet'!B90/'Ratio Analysis'!C30 -> 45.268212 | D31: ='Data Sheet'!C90/'Ratio Analysis'!D30 -> 58.396197 | E31: ='Data Sheet'!D90/'Ratio Analysis'!E30 -> 61.369358 | F31: ='Data Sheet'!E90/'Ratio Analysis'!F30 -> 77.864486 | G31: ='Data Sheet'!F90/'Ratio Analysis'!G30 -> 77.900002 | H31: ='Data Sheet'!G90/'Ratio Analysis'!H30 -> 53.388118 | I31: ='Data Sheet'!H90/'Ratio Analysis'!I30 -> 60.320103 | J31: ='Data Sheet'!I90/'Ratio Analysis'!J30 -> 53.922611 | ... L31: ='Data Sheet'!K90/'Ratio Analysis'!L30 -> 52.046755 | M31: =FORECAST($M$3,C31:L31,$C$3:$L$3) -> 57.320478 | N31: =FORECAST($M$3,D31:M31,$C$3:$L$3) -> 52.553253 | O31: =FORECAST($M$3,E31:N31,$C$3:$L$3) -> 48.575271 | P31: =FORECAST($M$3,F31:O31,$C$3:$L$3) -> 44.19323 | Q31: =FORECAST($M$3,G31:P31,$C$3:$L$3) -> 43.30499
B32: Book Value per Share | C32: =SUM('Historical FS'!C38:C39)/'Data Sheet'!B93 -> 31.16019 | D32: =SUM('Historical FS'!D38:D39)/'Data Sheet'!C93 -> 33.638254 | E32: =SUM('Historical FS'!E38:E39)/'Data Sheet'!D93 -> 36.342218 | F32: =SUM('Historical FS'!F38:F39)/'Data Sheet'!E93 -> 38.012749 | G32: =SUM('Historical FS'!G38:G39)/'Data Sheet'!F93 -> 202.90262 | H32: =SUM('Historical FS'!H38:H39)/'Data Sheet'!G93 -> 208.80575 | I32: =SUM('Historical FS'!I38:I39)/'Data Sheet'!H93 -> 214.09602 | J32: =SUM('Historical FS'!J38:J39)/'Data Sheet'!I93 -> 217.98604 | ... L32: =SUM('Historical FS'!L38:L39)/'Data Sheet'!K93 -> 207.43531 | M32: =FORECAST($M$3,C32:L32,$C$3:$L$3) -> 282.20645 | N32: =FORECAST($M$3,D32:M32,$C$3:$L$3) -> 310.0307 | O32: =FORECAST($M$3,E32:N32,$C$3:$L$3) -> 332.89261 | P32: =FORECAST($M$3,F32:O32,$C$3:$L$3) -> 347.20776 | Q32: =FORECAST($M$3,G32:P32,$C$3:$L$3) -> 347.92603
B34: Operating Cycle Ratios
B35: (in days)
B36: Inventory Days | C36: =365/C19 -> 50.441344 | D36: =365/D19 -> 47.139737 | E36: =365/E19 -> 44.617467 | F36: =365/F19 -> 48.485598 | G36: =365/G19 -> 50.030064 | H36: =365/H19 -> 51.358296 | I36: =365/I19 -> 43.669331 | J36: =365/J19 -> 43.59665 | ... L36: =365/L19 -> 47.900499 | M36: =FORECAST($M$3,C36:L36,$C$3:$L$3) -> 46.262294 | N36: =FORECAST($M$3,D36:M36,$C$3:$L$3) -> 46.554475 | O36: =FORECAST($M$3,E36:N36,$C$3:$L$3) -> 46.360877 | P36: =FORECAST($M$3,F36:O36,$C$3:$L$3) -> 45.456326 | Q36: =FORECAST($M$3,G36:P36,$C$3:$L$3) -> 45.106549
B37: Receivable Days | C37: =365/C20 -> 11.942133 | D37: =365/D20 -> 13.451962 | E37: =365/E20 -> 16.861867 | F37: =365/F20 -> 10.541814 | G37: =365/G20 -> 13.644425 | H37: =365/H20 -> 15.56153 | I37: =365/I20 -> 18.551255 | J37: =365/J20 -> 17.673275 | ... L37: =365/L20 -> 19.130964 | M37: =FORECAST($M$3,C37:L37,$C$3:$L$3) -> 21.328641 | N37: =FORECAST($M$3,D37:M37,$C$3:$L$3) -> 22.372934 | O37: =FORECAST($M$3,E37:N37,$C$3:$L$3) -> 23.61056 | P37: =FORECAST($M$3,F37:O37,$C$3:$L$3) -> 25.658048 | Q37: =FORECAST($M$3,G37:P37,$C$3:$L$3) -> 26.389474
B38: Payable Days | C38: =365/C21 -> 122.79817 | D38: =365/D21 -> 134.49738 | E38: =365/E21 -> 124.90811 | F38: =365/F21 -> 132.03433 | G38: =365/G21 -> 123.04125 | H38: =365/H21 -> 113.70045 | I38: =365/I21 -> 98.351017 | J38: =365/J21 -> 113.66347 | ... L38: =365/L21 -> 133.27921 | M38: =FORECAST($M$3,C38:L38,$C$3:$L$3) -> 116.6044 | N38: =FORECAST($M$3,D38:M38,$C$3:$L$3) -> 114.75402 | O38: =FORECAST($M$3,E38:N38,$C$3:$L$3) -> 115.69433 | P38: =FORECAST($M$3,F38:O38,$C$3:$L$3) -> 115.7697 | Q38: =FORECAST($M$3,G38:P38,$C$3:$L$3) -> 118.39404
